<?xml version="1.0"?>
<robot name="quadrotor">

  <!-- Define the link for the body -->
  <link name="body">
    <inertial>
      <mass value="1.0"/>  <!-- Mass of the drone -->
      <origin xyz="0 0 0" rpy="0 0 0"/>  <!-- Position and orientation -->
      <inertia  ixx="0.1" ixy="0" ixz="0" iyy="0.1" iyz="0" izz="0.1"/>
    </inertial>
    <visual>
      <geometry>
        <box size="0.5 0.5 0.1"/>  <!-- Size of the drone body -->
      </geometry>
      <origin xyz="0 0 0" rpy="0 0 0"/>
    </visual>
    <collision>
      <geometry>
        <box size="0.5 0.5 0.1"/>
      </geometry>
      <origin xyz="0 0 0" rpy="0 0 0"/>
    </collision>
  </link>

  <!-- Define the propellers -->
  <link name="propeller1">
    <inertial>
      <mass value="0.1"/>
      <origin xyz="0 0.3 0" rpy="0 0 0"/>
      <inertia  ixx="0.001" ixy="0" ixz="0" iyy="0.001" iyz="0" izz="0.001"/>
    </inertial>
    <visual>
      <geometry>
        <cylinder radius="0.05" length="0.1"/>  <!-- Propeller shape -->
      </geometry>
      <origin xyz="0 0.3 0" rpy="0 0 0"/>
    </visual>
    <collision>
      <geometry>
        <cylinder radius="0.05" length="0.1"/>
      </geometry>
      <origin xyz="0 0.3 0" rpy="0 0 0"/>
    </collision>
  </link>

  <link name="propeller2">
    <inertial>
      <mass value="0.1"/>
      <origin xyz="0 -0.3 0" rpy="0 0 0"/>
      <inertia  ixx="0.001" ixy="0" ixz="0" iyy="0.001" iyz="0" izz="0.001"/>
    </inertial>
    <visual>
      <geometry>
        <cylinder radius="0.05" length="0.1"/>
      </geometry>
      <origin xyz="0 -0.3 0" rpy="0 0 0"/>
    </visual>
    <collision>
      <geometry>
        <cylinder radius="0.05" length="0.1"/>
      </geometry>
      <origin xyz="0 -0.3 0" rpy="0 0 0"/>
    </collision>
  </link>

  <link name="propeller3">
    <inertial>
      <mass value="0.1"/>
      <origin xyz="0.3 0 0" rpy="0 0 0"/>
      <inertia  ixx="0.001" ixy="0" ixz="0" iyy="0.001" iyz="0" izz="0.001"/>
    </inertial>
    <visual>
      <geometry>
        <cylinder radius="0.05" length="0.1"/>
      </geometry>
      <origin xyz="0.3 0 0" rpy="0 0 0"/>
    </visual>
    <collision>
      <geometry>
        <cylinder radius="0.05" length="0.1"/>
      </geometry>
      <origin xyz="0.3 0 0" rpy="0 0 0"/>
    </collision>
  </link>

  <link name="propeller4">
    <inertial>
      <mass value="0.1"/>
      <origin xyz="-0.3 0 0" rpy="0 0 0"/>
      <inertia  ixx="0.001" ixy="0" ixz="0" iyy="0.001" iyz="0" izz="0.001"/>
    </inertial>
    <visual>
      <geometry>
        <cylinder radius="0.05" length="0.1"/>
      </geometry>
      <origin xyz="-0.3 0 0" rpy="0 0 0"/>
    </visual>
    <collision>
      <geometry>
        <cylinder radius="0.05" length="0.1"/>
      </geometry>
      <origin xyz="-0.3 0 0" rpy="0 0 0"/>
    </collision>
  </link>

  <!-- Define the joints that connect the body to the propellers -->
  <joint name="joint1" type="revolute">
    <parent link="body"/>
    <child link="propeller1"/>
    <origin xyz="0 0.3 0" rpy="0 0 0"/>
    <axis xyz="0 0 1"/>
  </joint>

  <joint name="joint2" type="revolute">
    <parent link="body"/>
    <child link="propeller2"/>
    <origin xyz="0 -0.3 0" rpy="0 0 0"/>
    <axis xyz="0 0 1"/>
  </joint>

  <joint name="joint3" type="revolute">
    <parent link="body"/>
    <child link="propeller3"/>
    <origin xyz="0.3 0 0" rpy="0 0 0"/>
    <axis xyz="0 0 1"/>
  </joint>

  <joint name="joint4" type="revolute">
    <parent link="body"/>
    <child link="propeller4"/>
    <origin xyz="-0.3 0 0" rpy="0 0 0"/>
    <axis xyz="0 0 1"/>
  </joint>

</robot>
